[2021-06-15 12:28:16,255] {taskinstance.py:876} INFO - Dependencies all met for <TaskInstance: sparkPipe.run_spark_file 2021-06-13T01:00:00+00:00 [queued]>
[2021-06-15 12:28:16,557] {taskinstance.py:876} INFO - Dependencies all met for <TaskInstance: sparkPipe.run_spark_file 2021-06-13T01:00:00+00:00 [queued]>
[2021-06-15 12:28:16,574] {taskinstance.py:1067} INFO - 
--------------------------------------------------------------------------------
[2021-06-15 12:28:16,577] {taskinstance.py:1068} INFO - Starting attempt 2 of 4
[2021-06-15 12:28:16,629] {taskinstance.py:1069} INFO - 
--------------------------------------------------------------------------------
[2021-06-15 12:28:16,870] {taskinstance.py:1087} INFO - Executing <Task(PythonOperator): run_spark_file> on 2021-06-13T01:00:00+00:00
[2021-06-15 12:28:17,225] {standard_task_runner.py:52} INFO - Started process 120 to run task
[2021-06-15 12:28:17,579] {standard_task_runner.py:76} INFO - Running: ['***', 'tasks', 'run', 'sparkPipe', 'run_spark_file', '2021-06-13T01:00:00+00:00', '--job-id', '9', '--pool', 'default_pool', '--raw', '--subdir', 'DAGS_FOLDER/run_spark_app.py', '--cfg-path', '/tmp/tmpwdek57ep', '--error-file', '/tmp/tmp3_15v2cw']
[2021-06-15 12:28:17,624] {standard_task_runner.py:77} INFO - Job 9: Subtask run_spark_file
[2021-06-15 12:28:19,426] {logging_mixin.py:104} INFO - Running <TaskInstance: sparkPipe.run_spark_file 2021-06-13T01:00:00+00:00 [running]> on host 15f1191013a9
[2021-06-15 12:28:21,444] {taskinstance.py:1282} INFO - Exporting the following env vars:
AIRFLOW_CTX_DAG_OWNER=***
AIRFLOW_CTX_DAG_ID=sparkPipe
AIRFLOW_CTX_TASK_ID=run_spark_file
AIRFLOW_CTX_EXECUTION_DATE=2021-06-13T01:00:00+00:00
AIRFLOW_CTX_DAG_RUN_ID=scheduled__2021-06-13T01:00:00+00:00
[2021-06-15 12:28:21,504] {taskinstance.py:1481} ERROR - Task failed with exception
Traceback (most recent call last):
  File "/home/airflow/.local/lib/python3.6/site-packages/airflow/models/taskinstance.py", line 1137, in _run_raw_task
    self._prepare_and_execute_task_with_callbacks(context, task)
  File "/home/airflow/.local/lib/python3.6/site-packages/airflow/models/taskinstance.py", line 1311, in _prepare_and_execute_task_with_callbacks
    result = self._execute_task(context, task_copy)
  File "/home/airflow/.local/lib/python3.6/site-packages/airflow/models/taskinstance.py", line 1341, in _execute_task
    result = task_copy.execute(context=context)
  File "/home/airflow/.local/lib/python3.6/site-packages/airflow/operators/python.py", line 150, in execute
    return_value = self.execute_callable()
  File "/home/airflow/.local/lib/python3.6/site-packages/airflow/operators/python.py", line 161, in execute_callable
    return self.python_callable(*self.op_args, **self.op_kwargs)
  File "/opt/airflow/dags/dependencies/ApiCalls.py", line 23, in urllib_sync_api_request
    r = requests.get('http:localhost:')
NameError: name 'requests' is not defined
[2021-06-15 12:28:21,630] {taskinstance.py:1531} INFO - Marking task as UP_FOR_RETRY. dag_id=sparkPipe, task_id=run_spark_file, execution_date=20210613T010000, start_date=20210615T122816, end_date=20210615T122821
[2021-06-15 12:28:23,689] {local_task_job.py:151} INFO - Task exited with return code 1
[2021-06-15 15:16:36,441] {taskinstance.py:876} INFO - Dependencies all met for <TaskInstance: sparkPipe.run_spark_file 2021-06-13T01:00:00+00:00 [queued]>
[2021-06-15 15:16:36,504] {taskinstance.py:876} INFO - Dependencies all met for <TaskInstance: sparkPipe.run_spark_file 2021-06-13T01:00:00+00:00 [queued]>
[2021-06-15 15:16:36,506] {taskinstance.py:1067} INFO - 
--------------------------------------------------------------------------------
[2021-06-15 15:16:36,507] {taskinstance.py:1068} INFO - Starting attempt 2 of 4
[2021-06-15 15:16:36,519] {taskinstance.py:1069} INFO - 
--------------------------------------------------------------------------------
[2021-06-15 15:16:36,555] {taskinstance.py:1087} INFO - Executing <Task(PythonOperator): run_spark_file> on 2021-06-13T01:00:00+00:00
[2021-06-15 15:16:36,574] {standard_task_runner.py:52} INFO - Started process 1752 to run task
[2021-06-15 15:16:36,596] {standard_task_runner.py:76} INFO - Running: ['***', 'tasks', 'run', 'sparkPipe', 'run_spark_file', '2021-06-13T01:00:00+00:00', '--job-id', '52', '--pool', 'default_pool', '--raw', '--subdir', 'DAGS_FOLDER/run_spark_app.py', '--cfg-path', '/tmp/tmp9_g872f5', '--error-file', '/tmp/tmpf60altjd']
[2021-06-15 15:16:36,599] {standard_task_runner.py:77} INFO - Job 52: Subtask run_spark_file
[2021-06-15 15:16:36,815] {logging_mixin.py:104} INFO - Running <TaskInstance: sparkPipe.run_spark_file 2021-06-13T01:00:00+00:00 [running]> on host 4c4793da73b7
[2021-06-15 15:16:37,008] {taskinstance.py:1282} INFO - Exporting the following env vars:
AIRFLOW_CTX_DAG_OWNER=***
AIRFLOW_CTX_DAG_ID=sparkPipe
AIRFLOW_CTX_TASK_ID=run_spark_file
AIRFLOW_CTX_EXECUTION_DATE=2021-06-13T01:00:00+00:00
AIRFLOW_CTX_DAG_RUN_ID=scheduled__2021-06-13T01:00:00+00:00
[2021-06-15 15:16:37,042] {taskinstance.py:1481} ERROR - Task failed with exception
Traceback (most recent call last):
  File "/home/airflow/.local/lib/python3.6/site-packages/urllib3/connection.py", line 160, in _new_conn
    (self._dns_host, self.port), self.timeout, **extra_kw
  File "/home/airflow/.local/lib/python3.6/site-packages/urllib3/util/connection.py", line 84, in create_connection
    raise err
  File "/home/airflow/.local/lib/python3.6/site-packages/urllib3/util/connection.py", line 74, in create_connection
    sock.connect(sa)
ConnectionRefusedError: [Errno 111] Connection refused

During handling of the above exception, another exception occurred:

Traceback (most recent call last):
  File "/home/airflow/.local/lib/python3.6/site-packages/urllib3/connectionpool.py", line 677, in urlopen
    chunked=chunked,
  File "/home/airflow/.local/lib/python3.6/site-packages/urllib3/connectionpool.py", line 392, in _make_request
    conn.request(method, url, **httplib_request_kw)
  File "/usr/local/lib/python3.6/http/client.py", line 1287, in request
    self._send_request(method, url, body, headers, encode_chunked)
  File "/usr/local/lib/python3.6/http/client.py", line 1333, in _send_request
    self.endheaders(body, encode_chunked=encode_chunked)
  File "/usr/local/lib/python3.6/http/client.py", line 1282, in endheaders
    self._send_output(message_body, encode_chunked=encode_chunked)
  File "/usr/local/lib/python3.6/http/client.py", line 1042, in _send_output
    self.send(msg)
  File "/usr/local/lib/python3.6/http/client.py", line 980, in send
    self.connect()
  File "/home/airflow/.local/lib/python3.6/site-packages/urllib3/connection.py", line 187, in connect
    conn = self._new_conn()
  File "/home/airflow/.local/lib/python3.6/site-packages/urllib3/connection.py", line 172, in _new_conn
    self, "Failed to establish a new connection: %s" % e
urllib3.exceptions.NewConnectionError: <urllib3.connection.HTTPConnection object at 0x7f829cd802b0>: Failed to establish a new connection: [Errno 111] Connection refused

During handling of the above exception, another exception occurred:

Traceback (most recent call last):
  File "/home/airflow/.local/lib/python3.6/site-packages/requests/adapters.py", line 449, in send
    timeout=timeout
  File "/home/airflow/.local/lib/python3.6/site-packages/urllib3/connectionpool.py", line 727, in urlopen
    method, url, error=e, _pool=self, _stacktrace=sys.exc_info()[2]
  File "/home/airflow/.local/lib/python3.6/site-packages/urllib3/util/retry.py", line 446, in increment
    raise MaxRetryError(_pool, url, error or ResponseError(cause))
urllib3.exceptions.MaxRetryError: HTTPConnectionPool(host='127.0.0.1', port=5000): Max retries exceeded with url: / (Caused by NewConnectionError('<urllib3.connection.HTTPConnection object at 0x7f829cd802b0>: Failed to establish a new connection: [Errno 111] Connection refused',))

During handling of the above exception, another exception occurred:

Traceback (most recent call last):
  File "/home/airflow/.local/lib/python3.6/site-packages/airflow/models/taskinstance.py", line 1137, in _run_raw_task
    self._prepare_and_execute_task_with_callbacks(context, task)
  File "/home/airflow/.local/lib/python3.6/site-packages/airflow/models/taskinstance.py", line 1311, in _prepare_and_execute_task_with_callbacks
    result = self._execute_task(context, task_copy)
  File "/home/airflow/.local/lib/python3.6/site-packages/airflow/models/taskinstance.py", line 1341, in _execute_task
    result = task_copy.execute(context=context)
  File "/home/airflow/.local/lib/python3.6/site-packages/airflow/operators/python.py", line 150, in execute
    return_value = self.execute_callable()
  File "/home/airflow/.local/lib/python3.6/site-packages/airflow/operators/python.py", line 161, in execute_callable
    return self.python_callable(*self.op_args, **self.op_kwargs)
  File "/opt/airflow/dags/dependencies/ApiCalls.py", line 14, in urllib_sync_api_request
    r = requests.get(url)
  File "/home/airflow/.local/lib/python3.6/site-packages/requests/api.py", line 76, in get
    return request('get', url, params=params, **kwargs)
  File "/home/airflow/.local/lib/python3.6/site-packages/requests/api.py", line 61, in request
    return session.request(method=method, url=url, **kwargs)
  File "/home/airflow/.local/lib/python3.6/site-packages/requests/sessions.py", line 542, in request
    resp = self.send(prep, **send_kwargs)
  File "/home/airflow/.local/lib/python3.6/site-packages/requests/sessions.py", line 655, in send
    r = adapter.send(request, **kwargs)
  File "/home/airflow/.local/lib/python3.6/site-packages/requests/adapters.py", line 516, in send
    raise ConnectionError(e, request=request)
requests.exceptions.ConnectionError: HTTPConnectionPool(host='127.0.0.1', port=5000): Max retries exceeded with url: / (Caused by NewConnectionError('<urllib3.connection.HTTPConnection object at 0x7f829cd802b0>: Failed to establish a new connection: [Errno 111] Connection refused',))
[2021-06-15 15:16:37,080] {taskinstance.py:1531} INFO - Marking task as UP_FOR_RETRY. dag_id=sparkPipe, task_id=run_spark_file, execution_date=20210613T010000, start_date=20210615T151636, end_date=20210615T151637
[2021-06-15 15:16:37,167] {local_task_job.py:151} INFO - Task exited with return code 1
